Workbook

Sheet 01_Executive_Dashboard
A1: RESEARCH INTELLIGENCE ENGINE (RIE) — COMMAND CENTER v1.0 | G1: DATA PROJECTION & SYSTEM STATUS
A2: Interactive Executive Console & Epistemic Governance Cockpit | Governed under Human Architect Level 5 — Human Architect | G2: Baseline: RIE_v1.5_GOLDEN_STATE | Rollback Anchors: v1.4.0 & v1.4.1 VERIFIED
A3: Cognitive Workflow: Question ➔ Discovery ➔ Understanding ➔ Verification ➔ Exploration ➔ Decision | G3: Phase Status: RIE v1.5 FULL CONTROLLED IMPLEMENTATION SEALED (PASS) | Mode: GOVERNED OPERATIONAL
A4: QUICK NAVIGATION: | B4: =HYPERLINK("#'02_Object_Registry'!A1", "➔ 2. OBJECT REGISTRY") | C4: =HYPERLINK("#'03_Relationship_Registry'!A1", "➔ 3. RELATIONSHIP REGISTRY") | D4: =HYPERLINK("#'04_Lineage_Explorer'!A1", "➔ 4. LINEAGE EXPLORER") | E4: =HYPERLINK("#'05_Knowledge_Frontier'!A1", "➔ 5. KNOWLEDGE FRONTIER") | F4: =HYPERLINK("#'06_Provenance_Register'!A1", "➔ 6. PROVENANCE REGISTER") | G4: =HYPERLINK("#'07_Human_Decision_Log'!A1", "➔ 7. HUMAN DECISION LOG") | H4: =HYPERLINK("#'DATA_KO'!A1", "➔ REPOSITORY DATA")
A6: 1. INTELLIGENCE INVENTORY & SUBSTRATE METRICS | E6: 2. HUMAN REVIEW STATUS (LEVEL 5 GOVERNANCE)
A7: Evidence Objects (EO) | B7: =COUNTA(DATA_EO!A2:A1000) | C7: Layer 1 ground truth empirical observations with exact timestamps | E7: Pending Review | F7: =COUNTIF(DATA_KO!H:H, "CANDIDATE") + COUNTIF(DATA_KO!H:H, "PENDING_HUMAN_REVIEW") | G7: Queued items awaiting Human Architect Level 5 evaluation
A8: Interpretation Objects (IO) | B8: =COUNTA(DATA_IO!A2:A1000) | C8: Layer 2 analytical models paired with competing counter-hypotheses | E8: Accepted (Ratified) | F8: =COUNTIF(DATA_KO!H:H, "CANONICAL") + COUNTIF(DATA_KO!I:I, "CANONICAL_RATIFIED") | G8: Knowledge objects formally ratified into Canonical status
A9: Knowledge Objects (KO) | B9: =COUNTA(DATA_KO!A2:A1000) | C9: Layer 3 synthesized institutional concepts awaiting Level 5 ratification | E9: Rejected / Quarantined | F9: =COUNTIF(DATA_KO!H:H, "REJECTED") + COUNTIF(DATA_KO!H:H, "QUARANTINED*") | G9: Rejected candidates & quarantined fixtures archived as negative/quarantined knowledge
A10: Total Relationships | B10: =COUNTA(DATA_RELATIONSHIPS!A2:A1000) | C10: Multi-layer semantic links (Substantiates, Synthesized Into, Coupled With) | E10: Deferred | F10: =COUNTIF(DATA_KO!H:H, "DEFERRED") + COUNTIF(DATA_KO!I:I, "CANDIDATE_REFINEMENT") | G10: Candidate concepts returned for further empirical refinement
A11: Origin Media Sources | B11: =COUNTA(DATA_SOURCE!A2:A1000) | C11: Verified upstream media source records ingested into repository | E11: Total Frontier Items | F11: =COUNTIF(DATA_KO!H:H, "CANDIDATE") + COUNTIF(DATA_KO!H:H, "PENDING_HUMAN_REVIEW") | G11: All queued items across candidate KOs, hypotheses, and frontiers
A13: 3. KNOWLEDGE FRONTIER FOCUS | E13: 4. SYSTEM STATUS & CANONICAL CONTROL
A14: Unresolved Frontier Items | B14: =COUNTIF(DATA_KO!H:H, "CANDIDATE") + COUNTIF(DATA_KO!H:H, "PENDING_HUMAN_REVIEW") | C14: Uncodified observations and hypotheses requiring human adjudication | E14: Current Production Baseline | F14: RIE_v1.5_GOLDEN_STATE | G14: Hybrid LLM Staged Batch + 10-Track Taxonomy v2.0 + AITG Bridge + SQLite Sidecar
A15: Candidate KOs | B15: =COUNTIF(DATA_KO!H:H, "CANDIDATE") | C15: Synthesized concepts pending formal Human Architect Level 5 ratification | E15: Development Candidate | F15: RIE_v1.4.1_REMEDIATED_SEALED | G15: Previous Golden State & v1.4.0 Rollback Anchor Preserved Untouched
A16: Pending Human Review | B16: =COUNTIF(DATA_KO!H:H, "PENDING_HUMAN_REVIEW") | C16: Candidate concepts routed to human architect review queue | E16: Validation Status | F16: PASS | G16: Validation Evidence: 21/21 Unit | 7/7 Adversarial | 6/6 v1.5 Feature Tests | ./rie audit PASS
A17: Total Epistemic Objects | B17: =(COUNTA(DATA_KO!A2:A1000)+COUNTA(DATA_IO!A2:A1000)+COUNTA(DATA_EO!A2:A1000)) | C17: Combined cardinality across Knowledge, Interpretation, and Evidence layers | E17: Promotion Status | F17: GOVERNED_OPERATIONAL_MODE | G17: RIE_COMMAND_CENTER.xlsx = SOLE HUMAN SSOT | rie_substrate.db = Performance Sidecar
A19: 5. INTELLIGENCE SEARCH & COGNITIVE DISCOVERY CONSOLE
A20: SEARCH KEYWORD: | B20: Enter Topic / Inquiry: | C20: Gold | D20: =HYPERLINK("#'01_Executive_Dashboard'!A20", "➔ [ SEARCH / REFRESH ]") | E20: =HYPERLINK("#'01_Executive_Dashboard'!A138", "➔ [ PREPARE INTELLIGENCE REPORT REQUEST ]")
A21: ACTIVE SELECTION: | B21: Selected KO for Investigation: | C21: {=IFERROR(INDEX(DATA_KO!A:A, MATCH(1, DATA_KO!K:K, 0)), "KO-FIN-DEBT-INTEREST-SPIRAL-001")} | D21: =HYPERLINK("#'04_Lineage_Explorer'!B6", "➔ [ OPEN LINEAGE EXPLORER ]") | E21: =IFERROR("Active Concept: " & VLOOKUP(C21, DATA_KO!A:B, 2, FALSE), "")
A22: ="SEARCH RESULTS FOR: " & UPPER($C$20) & " | Matched Knowledge Objects: " & COUNTIF(DATA_KO!J:J, 1) & " | Substrate Interpretations: " & COUNTIF(DATA_IO!J:J, 1) & " | Grounding Evidence: " & COUNTIF(DATA_EO!O:O, 1)
A23: HUMAN DECISION WORKFLOW: 1. Review Knowledge ➔ 2. Compare Evidence ➔ 3. Formulate Decision (ACCEPT / HOLD / REJECT / FURTHER RESEARCH) ➔ 4. [ RECORD DECISION IN LOG ]
A24: RETRIEVED KNOWLEDGE CONCEPTS (HUMAN MEANING FIRST — PROVENANCE LINEAGE ROOT)
A25: Concept Title (Human Meaning First) | B25: Object_ID & Domain | C25: Matched Because (Match Reason) | D25: Matched Specifics (Snippet) | E25: Substrate Profile | F25: Lineage Status | G25: Lineage Action | H25: Decision Action
A26: {=IFERROR(INDEX(DATA_KO!B:B, MATCH(1, DATA_KO!K:K, 0)), IF(1=1, "No intelligence objects found", ""))} | B26: {=IFERROR(INDEX(DATA_KO!A:A, MATCH(1, DATA_KO!K:K, 0)) & " | " & INDEX(DATA_KO!C:C, MATCH(1, DATA_KO!K:K, 0)), "")} | C26: {=IFERROR(INDEX(DATA_KO!O:O, MATCH(1, DATA_KO!K:K, 0)), "")} | D26: {=IFERROR(INDEX(DATA_KO!P:P, MATCH(1, DATA_KO!K:K, 0)), "")} | E26: {=IFERROR(INDEX(DATA_KO!T:T, MATCH(1, DATA_KO!K:K, 0)), "")} | F26: =IF(A26="","", IF(A26="No intelligence objects found", "", "LINKED")) | G26: =IF(A26="","", IF(A26="No intelligence objects found", "", HYPERLINK("#'04_Lineage_Explorer'!B6", "➔ Trace Lineage"))) | H26: =IF(A26="","", IF(A26="No intelligence objects found", "", HYPERLINK("#'07_Human_Decision_Log'!A1", "➔ Record Decision")))
A27: {=IFERROR(INDEX(DATA_KO!B:B, MATCH(2, DATA_KO!K:K, 0)), IF(2=1, "No intelligence objects found", ""))} | B27: {=IFERROR(INDEX(DATA_KO!A:A, MATCH(2, DATA_KO!K:K, 0)) & " | " & INDEX(DATA_KO!C:C, MATCH(2, DATA_KO!K:K, 0)), "")} | C27: {=IFERROR(INDEX(DATA_KO!O:O, MATCH(2, DATA_KO!K:K, 0)), "")} | D27: {=IFERROR(INDEX(DATA_KO!P:P, MATCH(2, DATA_KO!K:K, 0)), "")} | E27: {=IFERROR(INDEX(DATA_KO!T:T, MATCH(2, DATA_KO!K:K, 0)), "")} | F27: =IF(A27="","", IF(A27="No intelligence objects found", "", "LINKED")) | G27: =IF(A27="","", IF(A27="No intelligence objects found", "", HYPERLINK("#'04_Lineage_Explorer'!B6", "➔ Trace Lineage"))) | H27: =IF(A27="","", IF(A27="No intelligence objects found", "", HYPERLINK("#'07_Human_Decision_Log'!A1", "➔ Record Decision")))
A28: {=IFERROR(INDEX(DATA_KO!B:B, MATCH(3, DATA_KO!K:K, 0)), IF(3=1, "No intelligence objects found", ""))} | B28: {=IFERROR(INDEX(DATA_KO!A:A, MATCH(3, DATA_KO!K:K, 0)) & " | " & INDEX(DATA_KO!C:C, MATCH(3, DATA_KO!K:K, 0)), "")} | C28: {=IFERROR(INDEX(DATA_KO!O:O, MATCH(3, DATA_KO!K:K, 0)), "")} | D28: {=IFERROR(INDEX(DATA_KO!P:P, MATCH(3, DATA_KO!K:K, 0)), "")} | E28: {=IFERROR(INDEX(DATA_KO!T:T, MATCH(3, DATA_KO!K:K, 0)), "")} | F28: =IF(A28="","", IF(A28="No intelligence objects found", "", "LINKED")) | G28: =IF(A28="","", IF(A28="No intelligence objects found", "", HYPERLINK("#'04_Lineage_Explorer'!B6", "➔ Trace Lineage"))) | H28: =IF(A28="","", IF(A28="No intelligence objects found", "", HYPERLINK("#'07_Human_Decision_Log'!A1", "➔ Record Decision")))
A29: {=IFERROR(INDEX(DATA_KO!B:B, MATCH(4, DATA_KO!K:K, 0)), IF(4=1, "No intelligence objects found", ""))} | B29: {=IFERROR(INDEX(DATA_KO!A:A, MATCH(4, DATA_KO!K:K, 0)) & " | " & INDEX(DATA_KO!C:C, MATCH(4, DATA_KO!K:K, 0)), "")} | C29: {=IFERROR(INDEX(DATA_KO!O:O, MATCH(4, DATA_KO!K:K, 0)), "")} | D29: {=IFERROR(INDEX(DATA_KO!P:P, MATCH(4, DATA_KO!K:K, 0)), "")} | E29: {=IFERROR(INDEX(DATA_KO!T:T, MATCH(4, DATA_KO!K:K, 0)), "")} | F29: =IF(A29="","", IF(A29="No intelligence objects found", "", "LINKED")) | G29: =IF(A29="","", IF(A29="No intelligence objects found", "", HYPERLINK("#'04_Lineage_Explorer'!B6", "➔ Trace Lineage"))) | H29: =IF(A29="","", IF(A29="No intelligence objects found", "", HYPERLINK("#'07_Human_Decision_Log'!A1", "➔ Record Decision")))
A30: {=IFERROR(INDEX(DATA_KO!B:B, MATCH(5, DATA_KO!K:K, 0)), IF(5=1, "No intelligence objects found", ""))} | B30: {=IFERROR(INDEX(DATA_KO!A:A, MATCH(5, DATA_KO!K:K, 0)) & " | " & INDEX(DATA_KO!C:C, MATCH(5, DATA_KO!K:K, 0)), "")} | C30: {=IFERROR(INDEX(DATA_KO!O:O, MATCH(5, DATA_KO!K:K, 0)), "")} | D30: {=IFERROR(INDEX(DATA_KO!P:P, MATCH(5, DATA_KO!K:K, 0)), "")} | E30: {=IFERROR(INDEX(DATA_KO!T:T, MATCH(5, DATA_KO!K:K, 0)), "")} | F30: =IF(A30="","", IF(A30="No intelligence objects found", "", "LINKED")) | G30: =IF(A30="","", IF(A30="No intelligence objects found", "", HYPERLINK("#'04_Lineage_Explorer'!B6", "➔ Trace Lineage"))) | H30: =IF(A30="","", IF(A30="No intelligence objects found", "", HYPERLINK("#'07_Human_Decision_Log'!A1", "➔ Record Decision")))
A31: {=IFERROR(INDEX(DATA_KO!B:B, MATCH(6, DATA_KO!K:K, 0)), IF(6=1, "No intelligence objects found", ""))} | B31: {=IFERROR(INDEX(DATA_KO!A:A, MATCH(6, DATA_KO!K:K, 0)) & " | " & INDEX(DATA_KO!C:C, MATCH(6, DATA_KO!K:K, 0)), "")} | C31: {=IFERROR(INDEX(DATA_KO!O:O, MATCH(6, DATA_KO!K:K, 0)), "")} | D31: {=IFERROR(INDEX(DATA_KO!P:P, MATCH(6, DATA_KO!K:K, 0)), "")} | E31: {=IFERROR(INDEX(DATA_KO!T:T, MATCH(6, DATA_KO!K:K, 0)), "")} | F31: =IF(A31="","", IF(A31="No intelligence objects found", "", "LINKED")) | G31: =IF(A31="","", IF(A31="No intelligence objects found", "", HYPERLINK("#'04_Lineage_Explorer'!B6", "➔ Trace Lineage"))) | H31: =IF(A31="","", IF(A31="No intelligence objects found", "", HYPERLINK("#'07_Human_Decision_Log'!A1", "➔ Record Decision")))
A32: {=IFERROR(INDEX(DATA_KO!B:B, MATCH(7, DATA_KO!K:K, 0)), IF(7=1, "No intelligence objects found", ""))} | B32: {=IFERROR(INDEX(DATA_KO!A:A, MATCH(7, DATA_KO!K:K, 0)) & " | " & INDEX(DATA_KO!C:C, MATCH(7, DATA_KO!K:K, 0)), "")} | C32: {=IFERROR(INDEX(DATA_KO!O:O, MATCH(7, DATA_KO!K:K, 0)), "")} | D32: {=IFERROR(INDEX(DATA_KO!P:P, MATCH(7, DATA_KO!K:K, 0)), "")} | E32: {=IFERROR(INDEX(DATA_KO!T:T, MATCH(7, DATA_KO!K:K, 0)), "")} | F32: =IF(A32="","", IF(A32="No intelligence objects found", "", "LINKED")) | G32: =IF(A32="","", IF(A32="No intelligence objects found", "", HYPERLINK("#'04_Lineage_Explorer'!B6", "➔ Trace Lineage"))) | H32: =IF(A32="","", IF(A32="No intelligence objects found", "", HYPERLINK("#'07_Human_Decision_Log'!A1", "➔ Record Decision")))
A33: {=IFERROR(INDEX(DATA_KO!B:B, MATCH(8, DATA_KO!K:K, 0)), IF(8=1, "No intelligence objects found", ""))} | B33: {=IFERROR(INDEX(DATA_KO!A:A, MATCH(8, DATA_KO!K:K, 0)) & " | " & INDEX(DATA_KO!C:C, MATCH(8, DATA_KO!K:K, 0)), "")} | C33: {=IFERROR(INDEX(DATA_KO!O:O, MATCH(8, DATA_KO!K:K, 0)), "")} | D33: {=IFERROR(INDEX(DATA_KO!P:P, MATCH(8, DATA_KO!K:K, 0)), "")} | E33: {=IFERROR(INDEX(DATA_KO!T:T, MATCH(8, DATA_KO!K:K, 0)), "")} | F33: =IF(A33="","", IF(A33="No intelligence objects found", "", "LINKED")) | G33: =IF(A33="","", IF(A33="No intelligence objects found", "", HYPERLINK("#'04_Lineage_Explorer'!B6", "➔ Trace Lineage"))) | H33: =IF(A33="","", IF(A33="No intelligence objects found", "", HYPERLINK("#'07_Human_Decision_Log'!A1", "➔ Record Decision")))
A34: {=IFERROR(INDEX(DATA_KO!B:B, MATCH(9, DATA_KO!K:K, 0)), IF(9=1, "No intelligence objects found", ""))} | B34: {=IFERROR(INDEX(DATA_KO!A:A, MATCH(9, DATA_KO!K:K, 0)) & " | " & INDEX(DATA_KO!C:C, MATCH(9, DATA_KO!K:K, 0)), "")} | C34: {=IFERROR(INDEX(DATA_KO!O:O, MATCH(9, DATA_KO!K:K, 0)), "")} | D34: {=IFERROR(INDEX(DATA_KO!P:P, MATCH(9, DATA_KO!K:K, 0)), "")} | E34: {=IFERROR(INDEX(DATA_KO!T:T, MATCH(9, DATA_KO!K:K, 0)), "")} | F34: =IF(A34="","", IF(A34="No intelligence objects found", "", "LINKED")) | G34: =IF(A34="","", IF(A34="No intelligence objects found", "", HYPERLINK("#'04_Lineage_Explorer'!B6", "➔ Trace Lineage"))) | H34: =IF(A34="","", IF(A34="No intelligence objects found", "", HYPERLINK("#'07_Human_Decision_Log'!A1", "➔ Record Decision")))
A35: {=IFERROR(INDEX(DATA_KO!B:B, MATCH(10, DATA_KO!K:K, 0)), IF(10=1, "No intelligence objects found", ""))} | B35: {=IFERROR(INDEX(DATA_KO!A:A, MATCH(10, DATA_KO!K:K, 0)) & " | " & INDEX(DATA_KO!C:C, MATCH(10, DATA_KO!K:K, 0)), "")} | C35: {=IFERROR(INDEX(DATA_KO!O:O, MATCH(10, DATA_KO!K:K, 0)), "")} | D35: {=IFERROR(INDEX(DATA_KO!P:P, MATCH(10, DATA_KO!K:K, 0)), "")} | E35: {=IFERROR(INDEX(DATA_KO!T:T, MATCH(10, DATA_KO!K:K, 0)), "")} | F35: =IF(A35="","", IF(A35="No intelligence objects found", "", "LINKED")) | G35: =IF(A35="","", IF(A35="No intelligence objects found", "", HYPERLINK("#'04_Lineage_Explorer'!B6", "➔ Trace Lineage"))) | H35: =IF(A35="","", IF(A35="No intelligence objects found", "", HYPERLINK("#'07_Human_Decision_Log'!A1", "➔ Record Decision")))
A36: Hierarchical Discovery Tree (Collapsed by Default — Click [+] on Left Margin to Expand Supporting Interpretations & Evidence)
A37: 6. DYNAMIC INTELLIGENCE TREE EXPLORER (MULTI-KO TOPIC DISCOVERY & EXPANSION)
A38: Hierarchical Discovery Tree (Collapsed by Default — Click [+] on Left Margin to Expand Supporting Interpretations & Evidence)
A39: EXPLORATION LENS: | B39: ="Search Topic: " & UPPER($C$20) & " | Retrieved Knowledge Clusters: " & MAX(DATA_KO!K:K) | G39: =HYPERLINK("#'01_Executive_Dashboard'!A20", "➔ [Refresh Tree / New Search]")
A41: {=IFERROR(IF(INDEX(DATA_KO!A:A, MATCH(1, DATA_KO!K:K, 0))="","", "▼ Concept:"), "")} | B41: {=IFERROR(IF(INDEX(DATA_KO!A:A, MATCH(1, DATA_KO!K:K, 0))="","", INDEX(DATA_KO!B:B, MATCH(1, DATA_KO!K:K, 0))), "")} | E41: {=IFERROR(IF(INDEX(DATA_KO!A:A, MATCH(1, DATA_KO!K:K, 0))="","", "[[" & INDEX(DATA_KO!A:A, MATCH(1, DATA_KO!K:K, 0)) & "]]"), "")} | F41: {=IFERROR(IF(INDEX(DATA_KO!A:A, MATCH(1, DATA_KO!K:K, 0))="","", "IO: " & INDEX(DATA_KO!R:R, MATCH(1, DATA_KO!K:K, 0)) & " | EO: " & INDEX(DATA_KO!Q:Q, MATCH(1, DATA_KO!K:K, 0)) & " | Conf: " & TEXT(INDEX(DATA_KO!G:G, MATCH(1, DATA_KO!K:K, 0)), "0.00")), "")} | G41: {=IFERROR(IF(INDEX(DATA_KO!A:A, MATCH(1, DATA_KO!K:K, 0))="","", "Domain: " & INDEX(DATA_KO!C:C, MATCH(1, DATA_KO!K:K, 0))), "")} | H41: {=IFERROR(IF(INDEX(DATA_KO!A:A, MATCH(1, DATA_KO!K:K, 0))="","", HYPERLINK("#'04_Lineage_Explorer'!B6", "➔ [Inspect Lineage]")), "")}
B42: {=IFERROR(IF(INDEX(DATA_KO!A:A, MATCH(1, DATA_KO!K:K, 0))="","", " ▼ Supporting Interpretations (Layer 2) — " & INDEX(DATA_KO!R:R, MATCH(1, DATA_KO!K:K, 0)) & " Models"), "")}
B43: {=IFERROR(IF(INDEX(DATA_KO!A:A, MATCH(1, DATA_KO!K:K, 0))="","", " • [[" & TRIM(MID(SUBSTITUTE(INDEX(DATA_KO!F:F, MATCH(1, DATA_KO!K:K, 0)), ",", REPT(" ", 500)), 1, 500)) & "]] — " & INDEX(DATA_IO!B:B, MATCH(TRIM(MID(SUBSTITUTE(INDEX(DATA_KO!F:F, MATCH(1, DATA_KO!K:K, 0)), ",", REPT(" ", 500)), 1, 500)), DATA_IO!A:A, 0))), "")}
B44: {=IFERROR(IF(INDEX(DATA_KO!A:A, MATCH(1, DATA_KO!K:K, 0))="","", IF(ISERROR(FIND(",", INDEX(DATA_KO!F:F, MATCH(1, DATA_KO!K:K, 0)))), "", " • [[" & TRIM(MID(SUBSTITUTE(INDEX(DATA_KO!F:F, MATCH(1, DATA_KO!K:K, 0)), ",", REPT(" ", 500)), 501, 500)) & "]] — " & INDEX(DATA_IO!B:B, MATCH(TRIM(MID(SUBSTITUTE(INDEX(DATA_KO!F:F, MATCH(1, DATA_KO!K:K, 0)), ",", REPT(" ", 500)), 501, 500)), DATA_IO!A:A, 0)))), "")}
...

Sheet 02_Object_Registry
A1: RESEARCH INTELLIGENCE ENGINE (RIE) — UNIFIED OBJECT REGISTRY PORTAL | G1: =HYPERLINK("#'01_Executive_Dashboard'!A1", "⮌ BACK TO DASHBOARD") | H1: =HYPERLINK("#'04_Lineage_Explorer'!A1", "➔ LINEAGE EXPLORER")
A2: ="Authoritative Epistemic Inventory (" & COUNTA(DATA_KO!A2:A1000) & " KOs, " & COUNTA(DATA_IO!A2:A1000) & " IOs, " & COUNTA(DATA_EO!A2:A1000) & " EOs = " & (COUNTA(DATA_KO!A2:A1000)+COUNTA(DATA_IO!A2:A1000)+COUNTA(DATA_EO!A2:A1000)) & " Total Objects) | Substrate Dynamic Projection"
A4: Dedicated Object Layer | B4: Count | C4: Layer Definition | D4: Direct Registry Access | E4: Confidence | F4: Workflow / Review Status | G4: Supporting References | H4: Lineage Action
A5: 02A: Knowledge Objects (KO) | B5: =COUNTA(DATA_KO!A2:A1000) | C5: Layer 3 synthesized institutional concepts awaiting Level 5 ratification | D5: =HYPERLINK("#'02A_KO_Registry'!A1", "➔ OPEN KO REGISTRY") | E5: 0.88 | F5: CANDIDATE | G5: CANDIDATE_QUEUE | H5: None
A6: 02B: Interpretation Objects (IO) | B6: =COUNTA(DATA_IO!A2:A1000) | C6: Layer 2 analytical models paired with competing counter-hypotheses | D6: =HYPERLINK("#'02B_IO_Registry'!A1", "➔ OPEN IO REGISTRY") | E6: 0.9 | F6: CANDIDATE | G6: CANDIDATE_QUEUE | H6: None
A7: 02C: Evidence Objects (EO) | B7: =COUNTA(DATA_EO!A2:A1000) | C7: Layer 1 ground truth empirical observations with exact timestamps | D7: =HYPERLINK("#'02C_EO_Registry'!A1", "➔ OPEN EO REGISTRY") | E7: 0.82 | F7: CANDIDATE | G7: CANDIDATE_QUEUE | H7: None
A8: KO-FIN-MINER-RATIO-BREAKOUT-001 | B8: KO | C8: Mining Equity Operating Leverage Base Breakout Dynamics | D8: Equity Technical Analysis / Resource Economics | E8: 0.86 | F8: CANDIDATE | G8: CANDIDATE_QUEUE | H8: None
A9: UNIFIED KNOWLEDGE OBJECT (KO) ACTIVE SUBSTRATE PROJECTION | B9: KO | C9: Pre-emptive Tightening Discounting and Policy Announcement Bottoms | D9: Macro Economics / Monetary Transmission | E9: 0.78 | F9: CANDIDATE | G9: CANDIDATE_QUEUE | H9: None
A10: Object_ID | B10: Object_Type | C10: Title / Concept | D10: Domain / Source Anchor | E10: Confidence | F10: Workflow / Review Status | G10: Supporting References | H10: Lineage Action
A11: =IF(DATA_KO!A2<>"",""&DATA_KO!A2,"") | B11: =IF(A11<>"","KO","") | C11: =IF(A11<>"",""&DATA_KO!B2,"") | D11: =IF(A11<>"",""&DATA_KO!C2,"") | E11: =IF(A11<>"",DATA_KO!G2,"") | F11: =IF(A11<>"",""&DATA_KO!H2,"") | G11: =IF(A11<>"",""&DATA_KO!E2,"") | H11: =IF(A11<>"","➔ Trace Lineage","")
A12: =IF(DATA_KO!A3<>"",""&DATA_KO!A3,"") | B12: =IF(A12<>"","KO","") | C12: =IF(A12<>"",""&DATA_KO!B3,"") | D12: =IF(A12<>"",""&DATA_KO!C3,"") | E12: =IF(A12<>"",DATA_KO!G3,"") | F12: =IF(A12<>"",""&DATA_KO!H3,"") | G12: =IF(A12<>"",""&DATA_KO!E3,"") | H12: =IF(A12<>"","➔ Trace Lineage","")
A13: =IF(DATA_KO!A4<>"",""&DATA_KO!A4,"") | B13: =IF(A13<>"","KO","") | C13: =IF(A13<>"",""&DATA_KO!B4,"") | D13: =IF(A13<>"",""&DATA_KO!C4,"") | E13: =IF(A13<>"",DATA_KO!G4,"") | F13: =IF(A13<>"",""&DATA_KO!H4,"") | G13: =IF(A13<>"",""&DATA_KO!E4,"") | H13: =IF(A13<>"","➔ Trace Lineage","")
A14: =IF(DATA_KO!A5<>"",""&DATA_KO!A5,"") | B14: =IF(A14<>"","KO","") | C14: =IF(A14<>"",""&DATA_KO!B5,"") | D14: =IF(A14<>"",""&DATA_KO!C5,"") | E14: =IF(A14<>"",DATA_KO!G5,"") | F14: =IF(A14<>"",""&DATA_KO!H5,"") | G14: =IF(A14<>"",""&DATA_KO!E5,"") | H14: =IF(A14<>"","➔ Trace Lineage","")
A15: =IF(DATA_KO!A6<>"",""&DATA_KO!A6,"") | B15: =IF(A15<>"","KO","") | C15: =IF(A15<>"",""&DATA_KO!B6,"") | D15: =IF(A15<>"",""&DATA_KO!C6,"") | E15: =IF(A15<>"",DATA_KO!G6,"") | F15: =IF(A15<>"",""&DATA_KO!H6,"") | G15: =IF(A15<>"",""&DATA_KO!E6,"") | H15: =IF(A15<>"","➔ Trace Lineage","")
A16: =IF(DATA_KO!A7<>"",""&DATA_KO!A7,"") | B16: =IF(A16<>"","KO","") | C16: =IF(A16<>"",""&DATA_KO!B7,"") | D16: =IF(A16<>"",""&DATA_KO!C7,"") | E16: =IF(A16<>"",DATA_KO!G7,"") | F16: =IF(A16<>"",""&DATA_KO!H7,"") | G16: =IF(A16<>"",""&DATA_KO!E7,"") | H16: =IF(A16<>"","➔ Trace Lineage","")
A17: =IF(DATA_KO!A8<>"",""&DATA_KO!A8,"") | B17: =IF(A17<>"","KO","") | C17: =IF(A17<>"",""&DATA_KO!B8,"") | D17: =IF(A17<>"",""&DATA_KO!C8,"") | E17: =IF(A17<>"",DATA_KO!G8,"") | F17: =IF(A17<>"",""&DATA_KO!H8,"") | G17: =IF(A17<>"",""&DATA_KO!E8,"") | H17: =IF(A17<>"","➔ Trace Lineage","")
A18: =IF(DATA_KO!A9<>"",""&DATA_KO!A9,"") | B18: =IF(A18<>"","KO","") | C18: =IF(A18<>"",""&DATA_KO!B9,"") | D18: =IF(A18<>"",""&DATA_KO!C9,"") | E18: =IF(A18<>"",DATA_KO!G9,"") | F18: =IF(A18<>"",""&DATA_KO!H9,"") | G18: =IF(A18<>"",""&DATA_KO!E9,"") | H18: =IF(A18<>"","➔ Trace Lineage","")
A19: =IF(DATA_KO!A10<>"",""&DATA_KO!A10,"") | B19: =IF(A19<>"","KO","") | C19: =IF(A19<>"",""&DATA_KO!B10,"") | D19: =IF(A19<>"",""&DATA_KO!C10,"") | E19: =IF(A19<>"",DATA_KO!G10,"") | F19: =IF(A19<>"",""&DATA_KO!H10,"") | G19: =IF(A19<>"",""&DATA_KO!E10,"") | H19: =IF(A19<>"","➔ Trace Lineage","")
A20: =IF(DATA_KO!A11<>"",""&DATA_KO!A11,"") | B20: =IF(A20<>"","KO","") | C20: =IF(A20<>"",""&DATA_KO!B11,"") | D20: =IF(A20<>"",""&DATA_KO!C11,"") | E20: =IF(A20<>"",DATA_KO!G11,"") | F20: =IF(A20<>"",""&DATA_KO!H11,"") | G20: =IF(A20<>"",""&DATA_KO!E11,"") | H20: =IF(A20<>"","➔ Trace Lineage","")
A21: =IF(DATA_KO!A12<>"",""&DATA_KO!A12,"") | B21: =IF(A21<>"","KO","") | C21: =IF(A21<>"",""&DATA_KO!B12,"") | D21: =IF(A21<>"",""&DATA_KO!C12,"") | E21: =IF(A21<>"",DATA_KO!G12,"") | F21: =IF(A21<>"",""&DATA_KO!H12,"") | G21: =IF(A21<>"",""&DATA_KO!E12,"") | H21: =IF(A21<>"","➔ Trace Lineage","")
A22: =IF(DATA_KO!A13<>"",""&DATA_KO!A13,"") | B22: =IF(A22<>"","KO","") | C22: =IF(A22<>"",""&DATA_KO!B13,"") | D22: =IF(A22<>"",""&DATA_KO!C13,"") | E22: =IF(A22<>"",DATA_KO!G13,"") | F22: =IF(A22<>"",""&DATA_KO!H13,"") | G22: =IF(A22<>"",""&DATA_KO!E13,"") | H22: =IF(A22<>"","➔ Trace Lineage","")
... A210: =IF(DATA_KO!A201<>"",""&DATA_KO!A201,"") | B210: =IF(A210<>"","KO","") | C210: =IF(A210<>"",""&DATA_KO!B201,"") | D210: =IF(A210<>"",""&DATA_KO!C201,"") | E210: =IF(A210<>"",DATA_KO!G201,"") | F210: =IF(A210<>"",""&DATA_KO!H201,"") | G210: =IF(A210<>"",""&DATA_KO!E201,"") | H210: =IF(A210<>"","➔ Trace Lineage","")

Sheet 02A_KO_Registry
A1: RESEARCH INTELLIGENCE ENGINE (RIE) — KNOWLEDGE OBJECT (KO) REGISTRY | G1: =HYPERLINK("#'01_Executive_Dashboard'!A1", "⮌ BACK TO DASHBOARD") | H1: =HYPERLINK("#'02B_IO_Registry'!A1", "➔ IO REGISTRY") | I1: =HYPERLINK("#'02C_EO_Registry'!A1", "➔ EO REGISTRY") | J1: =HYPERLINK("#'04_Lineage_Explorer'!A1", "➔ LINEAGE EXPLORER")
A2: ="Authoritative Knowledge Objects (" & COUNTA(DATA_KO!A2:A1000) & " KOs) | Substrate Dynamic Projection"
A4: Object_ID | B4: Object_Type | C4: Concept Title | D4: Domain | E4: Confidence | F4: Review Status | G4: Origin Source | H4: Supporting EOs | I4: Supporting IOs | J4: Lineage Action
A5: =IF(DATA_KO!A2<>"",""&DATA_KO!A2,"") | B5: =IF(A5<>"","KO","") | C5: =IF(A5<>"",""&DATA_KO!B2,"") | D5: =IF(A5<>"",""&DATA_KO!C2,"") | E5: =IF(A5<>"",DATA_KO!G2,"") | F5: =IF(A5<>"",""&DATA_KO!H2,"") | G5: =IF(A5<>"",""&DATA_KO!D2,"") | H5: =IF(A5<>"",""&DATA_KO!E2,"") | I5: =IF(A5<>"",""&DATA_KO!F2,"") | J5: =IF(A5<>"","➔ Inspect Lineage","")
A6: =IF(DATA_KO!A3<>"",""&DATA_KO!A3,"") | B6: =IF(A6<>"","KO","") | C6: =IF(A6<>"",""&DATA_KO!B3,"") | D6: =IF(A6<>"",""&DATA_KO!C3,"") | E6: =IF(A6<>"",DATA_KO!G3,"") | F6: =IF(A6<>"",""&DATA_KO!H3,"") | G6: =IF(A6<>"",""&DATA_KO!D3,"") | H6: =IF(A6<>"",""&DATA_KO!E3,"") | I6: =IF(A6<>"",""&DATA_KO!F3,"") | J6: =IF(A6<>"","➔ Inspect Lineage","")
A7: =IF(DATA_KO!A4<>"",""&DATA_KO!A4,"") | B7: =IF(A7<>"","KO","") | C7: =IF(A7<>"",""&DATA_KO!B4,"") | D7: =IF(A7<>"",""&DATA_KO!C4,"") | E7: =IF(A7<>"",DATA_KO!G4,"") | F7: =IF(A7<>"",""&DATA_KO!H4,"") | G7: =IF(A7<>"",""&DATA_KO!D4,"") | H7: =IF(A7<>"",""&DATA_KO!E4,"") | I7: =IF(A7<>"",""&DATA_KO!F4,"") | J7: =IF(A7<>"","➔ Inspect Lineage","")
A8: =IF(DATA_KO!A5<>"",""&DATA_KO!A5,"") | B8: =IF(A8<>"","KO","") | C8: =IF(A8<>"",""&DATA_KO!B5,"") | D8: =IF(A8<>"",""&DATA_KO!C5,"") | E8: =IF(A8<>"",DATA_KO!G5,"") | F8: =IF(A8<>"",""&DATA_KO!H5,"") | G8: =IF(A8<>"",""&DATA_KO!D5,"") | H8: =IF(A8<>"",""&DATA_KO!E5,"") | I8: =IF(A8<>"",""&DATA_KO!F5,"") | J8: =IF(A8<>"","➔ Inspect Lineage","")
A9: =IF(DATA_KO!A6<>"",""&DATA_KO!A6,"") | B9: =IF(A9<>"","KO","") | C9: =IF(A9<>"",""&DATA_KO!B6,"") | D9: =IF(A9<>"",""&DATA_KO!C6,"") | E9: =IF(A9<>"",DATA_KO!G6,"") | F9: =IF(A9<>"",""&DATA_KO!H6,"") | G9: =IF(A9<>"",""&DATA_KO!D6,"") | H9: =IF(A9<>"",""&DATA_KO!E6,"") | I9: =IF(A9<>"",""&DATA_KO!F6,"") | J9: =IF(A9<>"","➔ Inspect Lineage","")
A10: =IF(DATA_KO!A7<>"",""&DATA_KO!A7,"") | B10: =IF(A10<>"","KO","") | C10: =IF(A10<>"",""&DATA_KO!B7,"") | D10: =IF(A10<>"",""&DATA_KO!C7,"") | E10: =IF(A10<>"",DATA_KO!G7,"") | F10: =IF(A10<>"",""&DATA_KO!H7,"") | G10: =IF(A10<>"",""&DATA_KO!D7,"") | H10: =IF(A10<>"",""&DATA_KO!E7,"") | I10: =IF(A10<>"",""&DATA_KO!F7,"") | J10: =IF(A10<>"","➔ Inspect Lineage","")
A11: =IF(DATA_KO!A8<>"",""&DATA_KO!A8,"") | B11: =IF(A11<>"","KO","") | C11: =IF(A11<>"",""&DATA_KO!B8,"") | D11: =IF(A11<>"",""&DATA_KO!C8,"") | E11: =IF(A11<>"",DATA_KO!G8,"") | F11: =IF(A11<>"",""&DATA_KO!H8,"") | G11: =IF(A11<>"",""&DATA_KO!D8,"") | H11: =IF(A11<>"",""&DATA_KO!E8,"") | I11: =IF(A11<>"",""&DATA_KO!F8,"") | J11: =IF(A11<>"","➔ Inspect Lineage","")
A12: =IF(DATA_KO!A9<>"",""&DATA_KO!A9,"") | B12: =IF(A12<>"","KO","") | C12: =IF(A12<>"",""&DATA_KO!B9,"") | D12: =IF(A12<>"",""&DATA_KO!C9,"") | E12: =IF(A12<>"",DATA_KO!G9,"") | F12: =IF(A12<>"",""&DATA_KO!H9,"") | G12: =IF(A12<>"",""&DATA_KO!D9,"") | H12: =IF(A12<>"",""&DATA_KO!E9,"") | I12: =IF(A12<>"",""&DATA_KO!F9,"") | J12: =IF(A12<>"","➔ Inspect Lineage","")
A13: =IF(DATA_KO!A10<>"",""&DATA_KO!A10,"") | B13: =IF(A13<>"","KO","") | C13: =IF(A13<>"",""&DATA_KO!B10,"") | D13: =IF(A13<>"",""&DATA_KO!C10,"") | E13: =IF(A13<>"",DATA_KO!G10,"") | F13: =IF(A13<>"",""&DATA_KO!H10,"") | G13: =IF(A13<>"",""&DATA_KO!D10,"") | H13: =IF(A13<>"",""&DATA_KO!E10,"") | I13: =IF(A13<>"",""&DATA_KO!F10,"") | J13: =IF(A13<>"","➔ Inspect Lineage","")
A14: =IF(DATA_KO!A11<>"",""&DATA_KO!A11,"") | B14: =IF(A14<>"","KO","") | C14: =IF(A14<>"",""&DATA_KO!B11,"") | D14: =IF(A14<>"",""&DATA_KO!C11,"") | E14: =IF(A14<>"",DATA_KO!G11,"") | F14: =IF(A14<>"",""&DATA_KO!H11,"") | G14: =IF(A14<>"",""&DATA_KO!D11,"") | H14: =IF(A14<>"",""&DATA_KO!E11,"") | I14: =IF(A14<>"",""&DATA_KO!F11,"") | J14: =IF(A14<>"","➔ Inspect Lineage","")
A15: =IF(DATA_KO!A12<>"",""&DATA_KO!A12,"") | B15: =IF(A15<>"","KO","") | C15: =IF(A15<>"",""&DATA_KO!B12,"") | D15: =IF(A15<>"",""&DATA_KO!C12,"") | E15: =IF(A15<>"",DATA_KO!G12,"") | F15: =IF(A15<>"",""&DATA_KO!H12,"") | G15: =IF(A15<>"",""&DATA_KO!D12,"") | H15: =IF(A15<>"",""&DATA_KO!E12,"") | I15: =IF(A15<>"",""&DATA_KO!F12,"") | J15: =IF(A15<>"","➔ Inspect Lineage","")
A16: =IF(DATA_KO!A13<>"",""&DATA_KO!A13,"") | B16: =IF(A16<>"","KO","") | C16: =IF(A16<>"",""&DATA_KO!B13,"") | D16: =IF(A16<>"",""&DATA_KO!C13,"") | E16: =IF(A16<>"",DATA_KO!G13,"") | F16: =IF(A16<>"",""&DATA_KO!H13,"") | G16: =IF(A16<>"",""&DATA_KO!D13,"") | H16: =IF(A16<>"",""&DATA_KO!E13,"") | I16: =IF(A16<>"",""&DATA_KO!F13,"") | J16: =IF(A16<>"","➔ Inspect Lineage","")
... A254: =IF(DATA_KO!A251<>"",""&DATA_KO!A251,"") | B254: =IF(A254<>"","KO","") | C254: =IF(A254<>"",""&DATA_KO!B251,"") | D254: =IF(A254<>"",""&DATA_KO!C251,"") | E254: =IF(A254<>"",DATA_KO!G251,"") | F254: =IF(A254<>"",""&DATA_KO!H251,"") | G254: =IF(A254<>"",""&DATA_KO!D251,"") | H254: =IF(A254<>"",""&DATA_KO!E251,"") | I254: =IF(A254<>"",""&DATA_KO!F251,"") | J254: =IF(A254<>"","➔ Inspect Lineage","")

Sheet 02B_IO_Registry
A1: RESEARCH INTELLIGENCE ENGINE (RIE) — INTERPRETATION OBJECT (IO) REGISTRY | F1: =HYPERLINK("#'01_Executive_Dashboard'!A1", "⮌ BACK TO DASHBOARD") | G1: =HYPERLINK("#'02A_KO_Registry'!A1", "➔ KO REGISTRY") | H1: =HYPERLINK("#'02C_EO_Registry'!A1", "➔ EO REGISTRY")
A2: ="Authoritative Interpretation Objects (" & COUNTA(DATA_IO!A2:A1000) & " IOs) | Substrate Dynamic Projection"
A4: Object_ID | B4: Object_Type | C4: Research Question | D4: Primary Interpretation | E4: Alternative Interpretation | F4: Confidence | G4: Supporting EO | H4: Workflow Status
A5: =IF(DATA_IO!A2<>"",""&DATA_IO!A2,"") | B5: =IF(A5<>"","IO","") | C5: =IF(A5<>"",""&DATA_IO!B2,"") | D5: =IF(A5<>"",""&DATA_IO!C2,"") | E5: =IF(A5<>"",""&DATA_IO!D2,"") | F5: =IF(A5<>"",DATA_IO!G2,"") | G5: =IF(A5<>"",""&DATA_IO!E2,"") | H5: =IF(A5<>"","DERIVED","")
A6: =IF(DATA_IO!A3<>"",""&DATA_IO!A3,"") | B6: =IF(A6<>"","IO","") | C6: =IF(A6<>"",""&DATA_IO!B3,"") | D6: =IF(A6<>"",""&DATA_IO!C3,"") | E6: =IF(A6<>"",""&DATA_IO!D3,"") | F6: =IF(A6<>"",DATA_IO!G3,"") | G6: =IF(A6<>"",""&DATA_IO!E3,"") | H6: =IF(A6<>"","DERIVED","")
A7: =IF(DATA_IO!A4<>"",""&DATA_IO!A4,"") | B7: =IF(A7<>"","IO","") | C7: =IF(A7<>"",""&DATA_IO!B4,"") | D7: =IF(A7<>"",""&DATA_IO!C4,"") | E7: =IF(A7<>"",""&DATA_IO!D4,"") | F7: =IF(A7<>"",DATA_IO!G4,"") | G7: =IF(A7<>"",""&DATA_IO!E4,"") | H7: =IF(A7<>"","DERIVED","")
A8: =IF(DATA_IO!A5<>"",""&DATA_IO!A5,"") | B8: =IF(A8<>"","IO","") | C8: =IF(A8<>"",""&DATA_IO!B5,"") | D8: =IF(A8<>"",""&DATA_IO!C5,"") | E8: =IF(A8<>"",""&DATA_IO!D5,"") | F8: =IF(A8<>"",DATA_IO!G5,"") | G8: =IF(A8<>"",""&DATA_IO!E5,"") | H8: =IF(A8<>"","DERIVED","")
A9: =IF(DATA_IO!A6<>"",""&DATA_IO!A6,"") | B9: =IF(A9<>"","IO","") | C9: =IF(A9<>"",""&DATA_IO!B6,"") | D9: =IF(A9<>"",""&DATA_IO!C6,"") | E9: =IF(A9<>"",""&DATA_IO!D6,"") | F9: =IF(A9<>"",DATA_IO!G6,"") | G9: =IF(A9<>"",""&DATA_IO!E6,"") | H9: =IF(A9<>"","DERIVED","")
A10: =IF(DATA_IO!A7<>"",""&DATA_IO!A7,"") | B10: =IF(A10<>"","IO","") | C10: =IF(A10<>"",""&DATA_IO!B7,"") | D10: =IF(A10<>"",""&DATA_IO!C7,"") | E10: =IF(A10<>"",""&DATA_IO!D7,"") | F10: =IF(A10<>"",DATA_IO!G7,"") | G10: =IF(A10<>"",""&DATA_IO!E7,"") | H10: =IF(A10<>"","DERIVED","")
A11: =IF(DATA_IO!A8<>"",""&DATA_IO!A8,"") | B11: =IF(A11<>"","IO","") | C11: =IF(A11<>"",""&DATA_IO!B8,"") | D11: =IF(A11<>"",""&DATA_IO!C8,"") | E11: =IF(A11<>"",""&DATA_IO!D8,"") | F11: =IF(A11<>"",DATA_IO!G8,"") | G11: =IF(A11<>"",""&DATA_IO!E8,"") | H11: =IF(A11<>"","DERIVED","")
A12: =IF(DATA_IO!A9<>"",""&DATA_IO!A9,"") | B12: =IF(A12<>"","IO","") | C12: =IF(A12<>"",""&DATA_IO!B9,"") | D12: =IF(A12<>"",""&DATA_IO!C9,"") | E12: =IF(A12<>"",""&DATA_IO!D9,"") | F12: =IF(A12<>"",DATA_IO!G9,"") | G12: =IF(A12<>"",""&DATA_IO!E9,"") | H12: =IF(A12<>"","DERIVED","")
A13: =IF(DATA_IO!A10<>"",""&DATA_IO!A10,"") | B13: =IF(A13<>"","IO","") | C13: =IF(A13<>"",""&DATA_IO!B10,"") | D13: =IF(A13<>"",""&DATA_IO!C10,"") | E13: =IF(A13<>"",""&DATA_IO!D10,"") | F13: =IF(A13<>"",DATA_IO!G10,"") | G13: =IF(A13<>"",""&DATA_IO!E10,"") | H13: =IF(A13<>"","DERIVED","")
A14: =IF(DATA_IO!A11<>"",""&DATA_IO!A11,"") | B14: =IF(A14<>"","IO","") | C14: =IF(A14<>"",""&DATA_IO!B11,"") | D14: =IF(A14<>"",""&DATA_IO!C11,"") | E14: =IF(A14<>"",""&DATA_IO!D11,"") | F14: =IF(A14<>"",DATA_IO!G11,"") | G14: =IF(A14<>"",""&DATA_IO!E11,"") | H14: =IF(A14<>"","DERIVED","")
A15: =IF(DATA_IO!A12<>"",""&DATA_IO!A12,"") | B15: =IF(A15<>"","IO","") | C15: =IF(A15<>"",""&DATA_IO!B12,"") | D15: =IF(A15<>"",""&DATA_IO!C12,"") | E15: =IF(A15<>"",""&DATA_IO!D12,"") | F15: =IF(A15<>"",DATA_IO!G12,"") | G15: =IF(A15<>"",""&DATA_IO!E12,"") | H15: =IF(A15<>"","DERIVED","")
A16: =IF(DATA_IO!A13<>"",""&DATA_IO!A13,"") | B16: =IF(A16<>"","IO","") | C16: =IF(A16<>"",""&DATA_IO!B13,"") | D16: =IF(A16<>"",""&DATA_IO!C13,"") | E16: =IF(A16<>"",""&DATA_IO!D13,"") | F16: =IF(A16<>"",DATA_IO!G13,"") | G16: =IF(A16<>"",""&DATA_IO!E13,"") | H16: =IF(A16<>"","DERIVED","")
... A254: =IF(DATA_IO!A251<>"",""&DATA_IO!A251,"") | B254: =IF(A254<>"","IO","") | C254: =IF(A254<>"",""&DATA_IO!B251,"") | D254: =IF(A254<>"",""&DATA_IO!C251,"") | E254: =IF(A254<>"",""&DATA_IO!D251,"") | F254: =IF(A254<>"",DATA_IO!G251,"") | G254: =IF(A254<>"",""&DATA_IO!E251,"") | H254: =IF(A254<>"","DERIVED","")

Sheet 02C_EO_Registry
A1: RESEARCH INTELLIGENCE ENGINE (RIE) — EVIDENCE OBJECT (EO) REGISTRY | F1: =HYPERLINK("#'01_Executive_Dashboard'!A1", "⮌ BACK TO DASHBOARD") | G1: =HYPERLINK("#'02A_KO_Registry'!A1", "➔ KO REGISTRY") | H1: =HYPERLINK("#'02B_IO_Registry'!A1", "➔ IO REGISTRY")
A2: ="Authoritative Evidence Objects (" & COUNTA(DATA_EO!A2:A1000) & " EOs) | Substrate Dynamic Projection"
A4: Object_ID | B4: Object_Type | C4: Direct Empirical Observation | D4: Source_ID | E4: RIE_Domain | F4: Evidence_Type | G4: Timestamp / Page | H4: Linked_IO
A5: =IF(DATA_EO!A2<>"",""&DATA_EO!A2,"") | B5: =IF(A5<>"","EO","") | C5: =IF(A5<>"",""&DATA_EO!L2,"") | D5: =IF(A5<>"",""&DATA_EO!B2,"") | E5: =IF(A5<>"",""&DATA_EO!G2,"") | F5: =IF(A5<>"",""&DATA_EO!K2,"") | G5: =IF(A5<>"",""&DATA_EO!J2,"") | H5: =IF(A5<>"",""&DATA_EO!M2,"")
A6: =IF(DATA_EO!A3<>"",""&DATA_EO!A3,"") | B6: =IF(A6<>"","EO","") | C6: =IF(A6<>"",""&DATA_EO!L3,"") | D6: =IF(A6<>"",""&DATA_EO!B3,"") | E6: =IF(A6<>"",""&DATA_EO!G3,"") | F6: =IF(A6<>"",""&DATA_EO!K3,"") | G6: =IF(A6<>"",""&DATA_EO!J3,"") | H6: =IF(A6<>"",""&DATA_EO!M3,"")
A7: =IF(DATA_EO!A4<>"",""&DATA_EO!A4,"") | B7: =IF(A7<>"","EO","") | C7: =IF(A7<>"",""&DATA_EO!L4,"") | D7: =IF(A7<>"",""&DATA_EO!B4,"") | E7: =IF(A7<>"",""&DATA_EO!G4,"") | F7: =IF(A7<>"",""&DATA_EO!K4,"") | G7: =IF(A7<>"",""&DATA_EO!J4,"") | H7: =IF(A7<>"",""&DATA_EO!M4,"")
A8: =IF(DATA_EO!A5<>"",""&DATA_EO!A5,"") | B8: =IF(A8<>"","EO","") | C8: =IF(A8<>"",""&DATA_EO!L5,"") | D8: =IF(A8<>"",""&DATA_EO!B5,"") | E8: =IF(A8<>"",""&DATA_EO!G5,"") | F8: =IF(A8<>"",""&DATA_EO!K5,"") | G8: =IF(A8<>"",""&DATA_EO!J5,"") | H8: =IF(A8<>"",""&DATA_EO!M5,"")
A9: =IF(DATA_EO!A6<>"",""&DATA_EO!A6,"") | B9: =IF(A9<>"","EO","") | C9: =IF(A9<>"",""&DATA_EO!L6,"") | D9: =IF(A9<>"",""&DATA_EO!B6,"") | E9: =IF(A9<>"",""&DATA_EO!G6,"") | F9: =IF(A9<>"",""&DATA_EO!K6,"") | G9: =IF(A9<>"",""&DATA_EO!J6,"") | H9: =IF(A9<>"",""&DATA_EO!M6,"")
A10: =IF(DATA_EO!A7<>"",""&DATA_EO!A7,"") | B10: =IF(A10<>"","EO","") | C10: =IF(A10<>"",""&DATA_EO!L7,"") | D10: =IF(A10<>"",""&DATA_EO!B7,"") | E10: =IF(A10<>"",""&DATA_EO!G7,"") | F10: =IF(A10<>"",""&DATA_EO!K7,"") | G10: =IF(A10<>"",""&DATA_EO!J7,"") | H10: =IF(A10<>"",""&DATA_EO!M7,"")
A11: =IF(DATA_EO!A8<>"",""&DATA_EO!A8,"") | B11: =IF(A11<>"","EO","") | C11: =IF(A11<>"",""&DATA_EO!L8,"") | D11: =IF(A11<>"",""&DATA_EO!B8,"") | E11: =IF(A11<>"",""&DATA_EO!G8,"") | F11: =IF(A11<>"",""&DATA_EO!K8,"") | G11: =IF(A11<>"",""&DATA_EO!J8,"") | H11: =IF(A11<>"",""&DATA_EO!M8,"")
A12: =IF(DATA_EO!A9<>"",""&DATA_EO!A9,"") | B12: =IF(A12<>"","EO","") | C12: =IF(A12<>"",""&DATA_EO!L9,"") | D12: =IF(A12<>"",""&DATA_EO!B9,"") | E12: =IF(A12<>"",""&DATA_EO!G9,"") | F12: =IF(A12<>"",""&DATA_EO!K9,"") | G12: =IF(A12<>"",""&DATA_EO!J9,"") | H12: =IF(A12<>"",""&DATA_EO!M9,"")
A13: =IF(DATA_EO!A10<>"",""&DATA_EO!A10,"") | B13: =IF(A13<>"","EO","") | C13: =IF(A13<>"",""&DATA_EO!L10,"") | D13: =IF(A13<>"",""&DATA_EO!B10,"") | E13: =IF(A13<>"",""&DATA_EO!G10,"") | F13: =IF(A13<>"",""&DATA_EO!K10,"") | G13: =IF(A13<>"",""&DATA_EO!J10,"") | H13: =IF(A13<>"",""&DATA_EO!M10,"")
A14: =IF(DATA_EO!A11<>"",""&DATA_EO!A11,"") | B14: =IF(A14<>"","EO","") | C14: =IF(A14<>"",""&DATA_EO!L11,"") | D14: =IF(A14<>"",""&DATA_EO!B11,"") | E14: =IF(A14<>"",""&DATA_EO!G11,"") | F14: =IF(A14<>"",""&DATA_EO!K11,"") | G14: =IF(A14<>"",""&DATA_EO!J11,"") | H14: =IF(A14<>"",""&DATA_EO!M11,"")
A15: =IF(DATA_EO!A12<>"",""&DATA_EO!A12,"") | B15: =IF(A15<>"","EO","") | C15: =IF(A15<>"",""&DATA_EO!L12,"") | D15: =IF(A15<>"",""&DATA_EO!B12,"") | E15: =IF(A15<>"",""&DATA_EO!G12,"") | F15: =IF(A15<>"",""&DATA_EO!K12,"") | G15: =IF(A15<>"",""&DATA_EO!J12,"") | H15: =IF(A15<>"",""&DATA_EO!M12,"")
A16: =IF(DATA_EO!A13<>"",""&DATA_EO!A13,"") | B16: =IF(A16<>"","EO","") | C16: =IF(A16<>"",""&DATA_EO!L13,"") | D16: =IF(A16<>"",""&DATA_EO!B13,"") | E16: =IF(A16<>"",""&DATA_EO!G13,"") | F16: =IF(A16<>"",""&DATA_EO!K13,"") | G16: =IF(A16<>"",""&DATA_EO!J13,"") | H16: =IF(A16<>"",""&DATA_EO!M13,"")
... A304: =IF(DATA_EO!A301<>"",""&DATA_EO!A301,"") | B304: =IF(A304<>"","EO","") | C304: =IF(A304<>"",""&DATA_EO!L301,"") | D304: =IF(A304<>"",""&DATA_EO!B301,"") | E304: =IF(A304<>"",""&DATA_EO!G301,"") | F304: =IF(A304<>"",""&DATA_EO!K301,"") | G304: =IF(A304<>"",""&DATA_EO!J301,"") | H304: =IF(A304<>"",""&DATA_EO!M301,"")

Sheet 03_Relationship_Registry
A1: RESEARCH INTELLIGENCE ENGINE (RIE) — RELATIONSHIP REGISTRY | J1: =HYPERLINK("#'01_Executive_Dashboard'!A1", "⮌ BACK TO DASHBOARD")
A2: ="Multi-Layer Semantic Relational Matrix (" & COUNTA(DATA_RELATIONSHIPS!A2:A1000) & " Relationships) | Dynamic Projection"
A4: Relationship_ID | B4: Source_ID | C4: Source_Type | D4: Target_ID | E4: Target_Type | F4: Relationship_Vector | G4: Rel_Strength | H4: CMS_v1_Score | I4: Surfacing_Status | J4: Cluster_ID | K4: Provenance_Source | L4: Lineage_Inspection
A5: =IF(DATA_RELATIONSHIPS!B2<>"",""&DATA_RELATIONSHIPS!B2,"") | B5: =IF(A5<>"",""&DATA_RELATIONSHIPS!C2,"") | C5: =IF(A5<>"","KO","") | D5: =IF(A5<>"",""&DATA_RELATIONSHIPS!D2,"") | E5: =IF(A5<>"","KO","") | F5: =IF(A5<>"",""&DATA_RELATIONSHIPS!F2,"") | G5: =IF(A5<>"",DATA_RELATIONSHIPS!G2,"") | H5: =IF(A5<>"",DATA_RELATIONSHIPS!G2,"") | I5: =IF(A5<>"",""&DATA_RELATIONSHIPS!H2,"") | J5: =IF(A5<>"",""&DATA_RELATIONSHIPS!I2,"") | K5: DATA_RELATIONSHIPS (Interest Rate Expectation) | L5: =HYPERLINK("#'04_Lineage_Explorer'!A1", "➔ Trace Lineage")
A6: =IF(DATA_RELATIONSHIPS!B3<>"",""&DATA_RELATIONSHIPS!B3,"") | B6: =IF(A6<>"",""&DATA_RELATIONSHIPS!C3,"") | C6: =IF(A6<>"","KO","") | D6: =IF(A6<>"",""&DATA_RELATIONSHIPS!D3,"") | E6: =IF(A6<>"","KO","") | F6: =IF(A6<>"",""&DATA_RELATIONSHIPS!F3,"") | G6: =IF(A6<>"",DATA_RELATIONSHIPS!G3,"") | H6: =IF(A6<>"",DATA_RELATIONSHIPS!G3,"") | I6: =IF(A6<>"",""&DATA_RELATIONSHIPS!H3,"") | J6: =IF(A6<>"",""&DATA_RELATIONSHIPS!I3,"") | K6: DATA_RELATIONSHIPS (Yield Curve Transmission) | L6: =HYPERLINK("#'04_Lineage_Explorer'!A1", "➔ Trace Lineage")
A7: =IF(DATA_RELATIONSHIPS!B4<>"",""&DATA_RELATIONSHIPS!B4,"") | B7: =IF(A7<>"",""&DATA_RELATIONSHIPS!C4,"") | C7: =IF(A7<>"","KO","") | D7: =IF(A7<>"",""&DATA_RELATIONSHIPS!D4,"") | E7: =IF(A7<>"","KO","") | F7: =IF(A7<>"",""&DATA_RELATIONSHIPS!F4,"") | G7: =IF(A7<>"",DATA_RELATIONSHIPS!G4,"") | H7: =IF(A7<>"",DATA_RELATIONSHIPS!G4,"") | I7: =IF(A7<>"",""&DATA_RELATIONSHIPS!H4,"") | J7: =IF(A7<>"",""&DATA_RELATIONSHIPS!I4,"") | K7: DATA_RELATIONSHIPS (Institutional Capital Rotation) | L7: =HYPERLINK("#'04_Lineage_Explorer'!A1", "➔ Trace Lineage")
A8: =IF(DATA_RELATIONSHIPS!B5<>"",""&DATA_RELATIONSHIPS!B5,"") | B8: =IF(A8<>"",""&DATA_RELATIONSHIPS!C5,"") | C8: =IF(A8<>"","KO","") | D8: =IF(A8<>"",""&DATA_RELATIONSHIPS!D5,"") | E8: =IF(A8<>"","KO","") | F8: =IF(A8<>"",""&DATA_RELATIONSHIPS!F5,"") | G8: =IF(A8<>"",DATA_RELATIONSHIPS!G5,"") | H8: =IF(A8<>"",DATA_RELATIONSHIPS!G5,"") | I8: =IF(A8<>"",""&DATA_RELATIONSHIPS!H5,"") | J8: =IF(A8<>"",""&DATA_RELATIONSHIPS!I5,"") | K8: DATA_RELATIONSHIPS (Secular Valuation Benchmark) | L8: =HYPERLINK("#'04_Lineage_Explorer'!A1", "➔ Trace Lineage")
A9: =IF(DATA_RELATIONSHIPS!B6<>"",""&DATA_RELATIONSHIPS!B6,"") | B9: =IF(A9<>"",""&DATA_RELATIONSHIPS!C6,"") | C9: =IF(A9<>"","KO","") | D9: =IF(A9<>"",""&DATA_RELATIONSHIPS!D6,"") | E9: =IF(A9<>"","KO","") | F9: =IF(A9<>"",""&DATA_RELATIONSHIPS!F6,"") | G9: =IF(A9<>"",DATA_RELATIONSHIPS!G6,"") | H9: =IF(A9<>"",DATA_RELATIONSHIPS!G6,"") | I9: =IF(A9<>"",""&DATA_RELATIONSHIPS!H6,"") | J9: =IF(A9<>"",""&DATA_RELATIONSHIPS!I6,"") | K9: DATA_RELATIONSHIPS (Central Bank Signaling Arbitrage) | L9: =HYPERLINK("#'04_Lineage_Explorer'!A1", "➔ Trace Lineage")
A10: =IF(DATA_RELATIONSHIPS!B7<>"",""&DATA_RELATIONSHIPS!B7,"") | B10: =IF(A10<>"",""&DATA_RELATIONSHIPS!C7,"") | C10: =IF(A10<>"","KO","") | D10: =IF(A10<>"",""&DATA_RELATIONSHIPS!D7,"") | E10: =IF(A10<>"","KO","") | F10: =IF(A10<>"",""&DATA_RELATIONSHIPS!F7,"") | G10: =IF(A10<>"",DATA_RELATIONSHIPS!G7,"") | H10: =IF(A10<>"",DATA_RELATIONSHIPS!G7,"") | I10: =IF(A10<>"",""&DATA_RELATIONSHIPS!H7,"") | J10: =IF(A10<>"",""&DATA_RELATIONSHIPS!I7,"") | K10: DATA_RELATIONSHIPS (Debt Refinancing Term Premium) | L10: =HYPERLINK("#'04_Lineage_Explorer'!A1", "➔ Trace Lineage")
A11: =IF(DATA_RELATIONSHIPS!B8<>"",""&DATA_RELATIONSHIPS!B8,"") | B11: =IF(A11<>"",""&DATA_RELATIONSHIPS!C8,"") | C11: =IF(A11<>"","KO","") | D11: =IF(A11<>"",""&DATA_RELATIONSHIPS!D8,"") | E11: =IF(A11<>"","KO","") | F11: =IF(A11<>"",""&DATA_RELATIONSHIPS!F8,"") | G11: =IF(A11<>"",DATA_RELATIONSHIPS!G8,"") | H11: =IF(A11<>"",DATA_RELATIONSHIPS!G8,"") | I11: =IF(A11<>"",""&DATA_RELATIONSHIPS!H8,"") | J11: =IF(A11<>"",""&DATA_RELATIONSHIPS!I8,"") | K11: DATA_RELATIONSHIPS (Treasury Market Liquidity Vulnerability) | L11: =HYPERLINK("#'04_Lineage_Explorer'!A1", "➔ Trace Lineage")
A12: =IF(DATA_RELATIONSHIPS!B9<>"",""&DATA_RELATIONSHIPS!B9,"") | B12: =IF(A12<>"",""&DATA_RELATIONSHIPS!C9,"") | C12: =IF(A12<>"","KO","") | D12: =IF(A12<>"",""&DATA_RELATIONSHIPS!D9,"") | E12: =IF(A12<>"","KO","") | F12: =IF(A12<>"",""&DATA_RELATIONSHIPS!F9,"") | G12: =IF(A12<>"",DATA_RELATIONSHIPS!G9,"") | H12: =IF(A12<>"",DATA_RELATIONSHIPS!G9,"") | I12: =IF(A12<>"",""&DATA_RELATIONSHIPS!H9,"") | J12: =IF(A12<>"",""&DATA_RELATIONSHIPS!I9,"") | K12: DATA_RELATIONSHIPS (Fiscal Dominance Cost-Push Feedback) | L12: =HYPERLINK("#'04_Lineage_Explorer'!A1", "➔ Trace Lineage")
A13: =IF(DATA_RELATIONSHIPS!B10<>"",""&DATA_RELATIONSHIPS!B10,"") | B13: =IF(A13<>"",""&DATA_RELATIONSHIPS!C10,"") | C13: =IF(A13<>"","KO","") | D13: =IF(A13<>"",""&DATA_RELATIONSHIPS!D10,"") | E13: =IF(A13<>"","KO","") | F13: =IF(A13<>"",""&DATA_RELATIONSHIPS!F10,"") | G13: =IF(A13<>"",DATA_RELATIONSHIPS!G10,"") | H13: =IF(A13<>"",DATA_RELATIONSHIPS!G10,"") | I13: =IF(A13<>"",""&DATA_RELATIONSHIPS!H10,"") | J13: =IF(A13<>"",""&DATA_RELATIONSHIPS!I10,"") | K13: DATA_RELATIONSHIPS (Token Revenue-to-Debt Mismatch) | L13: =HYPERLINK("#'04_Lineage_Explorer'!A1", "➔ Trace Lineage")
A14: =IF(DATA_RELATIONSHIPS!B11<>"",""&DATA_RELATIONSHIPS!B11,"") | B14: =IF(A14<>"",""&DATA_RELATIONSHIPS!C11,"") | C14: =IF(A14<>"","KO","") | D14: =IF(A14<>"",""&DATA_RELATIONSHIPS!D11,"") | E14: =IF(A14<>"","KO","") | F14: =IF(A14<>"",""&DATA_RELATIONSHIPS!F11,"") | G14: =IF(A14<>"",DATA_RELATIONSHIPS!G11,"") | H14: =IF(A14<>"",DATA_RELATIONSHIPS!G11,"") | I14: =IF(A14<>"",""&DATA_RELATIONSHIPS!H11,"") | J14: =IF(A14<>"",""&DATA_RELATIONSHIPS!I11,"") | K14: DATA_RELATIONSHIPS (Off-Balance Sheet Refinancing Cliff) | L14: =HYPERLINK("#'04_Lineage_Explorer'!A1", "➔ Trace Lineage")
A15: =IF(DATA_RELATIONSHIPS!B12<>"",""&DATA_RELATIONSHIPS!B12,"") | B15: =IF(A15<>"",""&DATA_RELATIONSHIPS!C12,"") | C15: =IF(A15<>"","KO","") | D15: =IF(A15<>"",""&DATA_RELATIONSHIPS!D12,"") | E15: =IF(A15<>"","KO","") | F15: =IF(A15<>"",""&DATA_RELATIONSHIPS!F12,"") | G15: =IF(A15<>"",DATA_RELATIONSHIPS!G12,"") | H15: =IF(A15<>"",DATA_RELATIONSHIPS!G12,"") | I15: =IF(A15<>"",""&DATA_RELATIONSHIPS!H12,"") | J15: =IF(A15<>"",""&DATA_RELATIONSHIPS!I12,"") | K15: DATA_RELATIONSHIPS (Leveraged Liquidity Contagion) | L15: =HYPERLINK("#'04_Lineage_Explorer'!A1", "➔ Trace Lineage")
A16: =IF(DATA_RELATIONSHIPS!B13<>"",""&DATA_RELATIONSHIPS!B13,"") | B16: =IF(A16<>"",""&DATA_RELATIONSHIPS!C13,"") | C16: =IF(A16<>"","KO","") | D16: =IF(A16<>"",""&DATA_RELATIONSHIPS!D13,"") | E16: =IF(A16<>"","KO","") | F16: =IF(A16<>"",""&DATA_RELATIONSHIPS!F13,"") | G16: =IF(A16<>"",DATA_RELATIONSHIPS!G13,"") | H16: =IF(A16<>"",DATA_RELATIONSHIPS!G13,"") | I16: =IF(A16<>"",""&DATA_RELATIONSHIPS!H13,"") | J16: =IF(A16<>"",""&DATA_RELATIONSHIPS!I13,"") | K16: DATA_RELATIONSHIPS (Inverted Heuristic Trigger) | L16: =HYPERLINK("#'04_Lineage_Explorer'!A1", "➔ Trace Lineage")
... A21: =IF(DATA_RELATIONSHIPS!B18<>"",""&DATA_RELATIONSHIPS!B18,"") | B21: =IF(A21<>"",""&DATA_RELATIONSHIPS!C18,"") | C21: =IF(A21<>"","KO","") | D21: =IF(A21<>"",""&DATA_RELATIONSHIPS!D18,"") | E21: =IF(A21<>"","KO","") | F21: =IF(A21<>"",""&DATA_RELATIONSHIPS!F18,"") | G21: =IF(A21<>"",DATA_RELATIONSHIPS!G18,"") | H21: =IF(A21<>"",DATA_RELATIONSHIPS!G18,"") | I21: =IF(A21<>"",""&DATA_RELATIONSHIPS!H18,"") | J21: =IF(A21<>"",""&DATA_RELATIONSHIPS!I18,"") | K21: DATA_RELATIONSHIPS (Operating Margin Bull Confirmation) | L21: =HYPERLINK("#'04_Lineage_Explorer'!A1", "➔ Trace Lineage")
A22: =IF(DATA_RELATIONSHIPS!B19<>"",""&DATA_RELATIONSHIPS!B19,"") | B22: =IF(A22<>"",""&DATA_RELATIONSHIPS!C19,"") | C22: =IF(A22<>"","KO","") | D22: =IF(A22<>"",""&DATA_RELATIONSHIPS!D19,"") | E22: =IF(A22<>"","KO","") | F22: =IF(A22<>"",""&DATA_RELATIONSHIPS!F19,"") | G22: =IF(A22<>"",DATA_RELATIONSHIPS!G19,"") | H22: =IF(A22<>"",DATA_RELATIONSHIPS!G19,"") | I22: =IF(A22<>"",""&DATA_RELATIONSHIPS!H19,"") | J22: =IF(A22<>"",""&DATA_RELATIONSHIPS!I19,"") | K22: DATA_RELATIONSHIPS (Fiscal Vulnerability Weaponization)
A23: =IF(DATA_RELATIONSHIPS!B20<>"",""&DATA_RELATIONSHIPS!B20,"") | B23: =IF(A23<>"",""&DATA_RELATIONSHIPS!C20,"") | C23: =IF(A23<>"","KO","") | D23: =IF(A23<>"",""&DATA_RELATIONSHIPS!D20,"") | E23: =IF(A23<>"","KO","") | F23: =IF(A23<>"",""&DATA_RELATIONSHIPS!F20,"") | G23: =IF(A23<>"",DATA_RELATIONSHIPS!G20,"") | H23: =IF(A23<>"",DATA_RELATIONSHIPS!G20,"") | I23: =IF(A23<>"",""&DATA_RELATIONSHIPS!H20,"") | J23: =IF(A23<>"",""&DATA_RELATIONSHIPS!I20,"") | K23: DATA_RELATIONSHIPS (Cost-Push Policy Asymmetry Transmission)
A24: =IF(DATA_RELATIONSHIPS!B21<>"",""&DATA_RELATIONSHIPS!B21,"") | B24: =IF(A24<>"",""&DATA_RELATIONSHIPS!C21,"") | C24: =IF(A24<>"","KO","") | D24: =IF(A24<>"",""&DATA_RELATIONSHIPS!D21,"") | E24: =IF(A24<>"","KO","") | F24: =IF(A24<>"",""&DATA_RELATIONSHIPS!F21,"") | G24: =IF(A24<>"",DATA_RELATIONSHIPS!G21,"") | H24: =IF(A24<>"",DATA_RELATIONSHIPS!G21,"") | I24: =IF(A24<>"",""&DATA_RELATIONSHIPS!H21,"") | J24: =IF(A24<>"",""&DATA_RELATIONSHIPS!I21,"") | K24: DATA_RELATIONSHIPS (Reserve Divestment Countermeasure)
A25: =IF(DATA_RELATIONSHIPS!B22<>"",""&DATA_RELATIONSHIPS!B22,"") | B25: =IF(A25<>"",""&DATA_RELATIONSHIPS!C22,"") | C25: =IF(A25<>"","KO","") | D25: =IF(A25<>"",""&DATA_RELATIONSHIPS!D22,"") | E25: =IF(A25<>"","KO","") | F25: =IF(A25<>"",""&DATA_RELATIONSHIPS!F22,"") | G25: =IF(A25<>"",DATA_RELATIONSHIPS!G22,"") | H25: =IF(A25<>"",DATA_RELATIONSHIPS!G22,"") | I25: =IF(A25<>"",""&DATA_RELATIONSHIPS!H22,"") | J25: =IF(A25<>"",""&DATA_RELATIONSHIPS!I22,"") | K25: DATA_RELATIONSHIPS (Petrodollar Re-Anchoring Flow)
A26: =IF(DATA_RELATIONSHIPS!B23<>"",""&DATA_RELATIONSHIPS!B23,"") | B26: =IF(A26<>"",""&DATA_RELATIONSHIPS!C23,"") | C26: =IF(A26<>"","KO","") | D26: =IF(A26<>"",""&DATA_RELATIONSHIPS!D23,"") | E26: =IF(A26<>"","KO","") | F26: =IF(A26<>"",""&DATA_RELATIONSHIPS!F23,"") | G26: =IF(A26<>"",DATA_RELATIONSHIPS!G23,"") | H26: =IF(A26<>"",DATA_RELATIONSHIPS!G23,"") | I26: =IF(A26<>"",""&DATA_RELATIONSHIPS!H23,"") | J26: =IF(A26<>"",""&DATA_RELATIONSHIPS!I23,"") | K26: DATA_RELATIONSHIPS (Theological Perception Divergence)
A27: =IF(DATA_RELATIONSHIPS!B24<>"",""&DATA_RELATIONSHIPS!B24,"") | B27: =IF(A27<>"",""&DATA_RELATIONSHIPS!C24,"") | C27: =IF(A27<>"","KO","") | D27: =IF(A27<>"",""&DATA_RELATIONSHIPS!D24,"") | E27: =IF(A27<>"","KO","") | F27: =IF(A27<>"",""&DATA_RELATIONSHIPS!F24,"") | G27: =IF(A27<>"",DATA_RELATIONSHIPS!G24,"") | H27: =IF(A27<>"",DATA_RELATIONSHIPS!G24,"") | I27: =IF(A27<>"",""&DATA_RELATIONSHIPS!H24,"") | J27: =IF(A27<>"",""&DATA_RELATIONSHIPS!I24,"") | K27: DATA_RELATIONSHIPS (Macro Tail-Risk Tactical Hedging)
A28: =IF(DATA_RELATIONSHIPS!B25<>"",""&DATA_RELATIONSHIPS!B25,"") | B28: =IF(A28<>"",""&DATA_RELATIONSHIPS!C25,"") | C28: =IF(A28<>"","KO","") | D28: =IF(A28<>"",""&DATA_RELATIONSHIPS!D25,"") | E28: =IF(A28<>"","KO","") | F28: =IF(A28<>"",""&DATA_RELATIONSHIPS!F25,"") | G28: =IF(A28<>"",DATA_RELATIONSHIPS!G25,"") | H28: =IF(A28<>"",DATA_RELATIONSHIPS!G25,"") | I28: =IF(A28<>"",""&DATA_RELATIONSHIPS!H25,"") | J28: =IF(A28<>"",""&DATA_RELATIONSHIPS!I25,"")
A29: =IF(DATA_RELATIONSHIPS!B26<>"",""&DATA_RELATIONSHIPS!B26,"") | B29: =IF(A29<>"",""&DATA_RELATIONSHIPS!C26,"") | C29: =IF(A29<>"","KO","") | D29: =IF(A29<>"",""&DATA_RELATIONSHIPS!D26,"") | E29: =IF(A29<>"","KO","") | F29: =IF(A29<>"",""&DATA_RELATIONSHIPS!F26,"") | G29: =IF(A29<>"",DATA_RELATIONSHIPS!G26,"") | H29: =IF(A29<>"",DATA_RELATIONSHIPS!G26,"") | I29: =IF(A29<>"",""&DATA_RELATIONSHIPS!H26,"") | J29: =IF(A29<>"",""&DATA_RELATIONSHIPS!I26,"")
A30: =IF(DATA_RELATIONSHIPS!B27<>"",""&DATA_RELATIONSHIPS!B27,"") | B30: =IF(A30<>"",""&DATA_RELATIONSHIPS!C27,"") | C30: =IF(A30<>"","KO","") | D30: =IF(A30<>"",""&DATA_RELATIONSHIPS!D27,"") | E30: =IF(A30<>"","KO","") | F30: =IF(A30<>"",""&DATA_RELATIONSHIPS!F27,"") | G30: =IF(A30<>"",DATA_RELATIONSHIPS!G27,"") | H30: =IF(A30<>"",DATA_RELATIONSHIPS!G27,"") | I30: =IF(A30<>"",""&DATA_RELATIONSHIPS!H27,"") | J30: =IF(A30<>"",""&DATA_RELATIONSHIPS!I27,"")
A31: =IF(DATA_RELATIONSHIPS!B28<>"",""&DATA_RELATIONSHIPS!B28,"") | B31: =IF(A31<>"",""&DATA_RELATIONSHIPS!C28,"") | C31: =IF(A31<>"","KO","") | D31: =IF(A31<>"",""&DATA_RELATIONSHIPS!D28,"") | E31: =IF(A31<>"","KO","") | F31: =IF(A31<>"",""&DATA_RELATIONSHIPS!F28,"") | G31: =IF(A31<>"",DATA_RELATIONSHIPS!G28,"") | H31: =IF(A31<>"",DATA_RELATIONSHIPS!G28,"") | I31: =IF(A31<>"",""&DATA_RELATIONSHIPS!H28,"") | J31: =IF(A31<>"",""&DATA_RELATIONSHIPS!I28,"")
A32: =IF(DATA_RELATIONSHIPS!B29<>"",""&DATA_RELATIONSHIPS!B29,"") | B32: =IF(A32<>"",""&DATA_RELATIONSHIPS!C29,"") | C32: =IF(A32<>"","KO","") | D32: =IF(A32<>"",""&DATA_RELATIONSHIPS!D29,"") | E32: =IF(A32<>"","KO","") | F32: =IF(A32<>"",""&DATA_RELATIONSHIPS!F29,"") | G32: =IF(A32<>"",DATA_RELATIONSHIPS!G29,"") | H32: =IF(A32<>"",DATA_RELATIONSHIPS!G29,"") | I32: =IF(A32<>"",""&DATA_RELATIONSHIPS!H29,"") | J32: =IF(A32<>"",""&DATA_RELATIONSHIPS!I29,"")
A33: =IF(DATA_RELATIONSHIPS!B30<>"",""&DATA_RELATIONSHIPS!B30,"") | B33: =IF(A33<>"",""&DATA_RELATIONSHIPS!C30,"") | C33: =IF(A33<>"","KO","") | D33: =IF(A33<>"",""&DATA_RELATIONSHIPS!D30,"") | E33: =IF(A33<>"","KO","") | F33: =IF(A33<>"",""&DATA_RELATIONSHIPS!F30,"") | G33: =IF(A33<>"",DATA_RELATIONSHIPS!G30,"") | H33: =IF(A33<>"",DATA_RELATIONSHIPS!G30,"") | I33: =IF(A33<>"",""&DATA_RELATIONSHIPS!H30,"") | J33: =IF(A33<>"",""&DATA_RELATIONSHIPS!I30,"")
A34: =IF(DATA_RELATIONSHIPS!B31<>"",""&DATA_RELATIONSHIPS!B31,"") | B34: =IF(A34<>"",""&DATA_RELATIONSHIPS!C31,"") | C34: =IF(A34<>"","KO","") | D34: =IF(A34<>"",""&DATA_RELATIONSHIPS!D31,"") | E34: =IF(A34<>"","KO","") | F34: =IF(A34<>"",""&DATA_RELATIONSHIPS!F31,"") | G34: =IF(A34<>"",DATA_RELATIONSHIPS!G31,"") | H34: =IF(A34<>"",DATA_RELATIONSHIPS!G31,"") | I34: =IF(A34<>"",""&DATA_RELATIONSHIPS!H31,"") | J34: =IF(A34<>"",""&DATA_RELATIONSHIPS!I31,"")
A35: =IF(DATA_RELATIONSHIPS!B32<>"",""&DATA_RELATIONSHIPS!B32,"") | B35: =IF(A35<>"",""&DATA_RELATIONSHIPS!C32,"") | C35: =IF(A35<>"","KO","") | D35: =IF(A35<>"",""&DATA_RELATIONSHIPS!D32,"") | E35: =IF(A35<>"","KO","") | F35: =IF(A35<>"",""&DATA_RELATIONSHIPS!F32,"") | G35: =IF(A35<>"",DATA_RELATIONSHIPS!G32,"") | H35: =IF(A35<>"",DATA_RELATIONSHIPS!G32,"") | I35: =IF(A35<>"",""&DATA_RELATIONSHIPS!H32,"") | J35: =IF(A35<>"",""&DATA_RELATIONSHIPS!I32,"")
A36: =IF(DATA_RELATIONSHIPS!B33<>"",""&DATA_RELATIONSHIPS!B33,"") | B36: =IF(A36<>"",""&DATA_RELATIONSHIPS!C33,"") | C36: =IF(A36<>"","KO","") | D36: =IF(A36<>"",""&DATA_RELATIONSHIPS!D33,"") | E36: =IF(A36<>"","KO","") | F36: =IF(A36<>"",""&DATA_RELATIONSHIPS!F33,"") | G36: =IF(A36<>"",DATA_RELATIONSHIPS!G33,"") | H36: =IF(A36<>"",DATA_RELATIONSHIPS!G33,"") | I36: =IF(A36<>"",""&DATA_RELATIONSHIPS!H33,"") | J36: =IF(A36<>"",""&DATA_RELATIONSHIPS!I33,"")
A37: =IF(DATA_RELATIONSHIPS!B34<>"",""&DATA_RELATIONSHIPS!B34,"") | B37: =IF(A37<>"",""&DATA_RELATIONSHIPS!C34,"") | C37: =IF(A37<>"","KO","") | D37: =IF(A37<>"",""&DATA_RELATIONSHIPS!D34,"") | E37: =IF(A37<>"","KO","") | F37: =IF(A37<>"",""&DATA_RELATIONSHIPS!F34,"") | G37: =IF(A37<>"",DATA_RELATIONSHIPS!G34,"") | H37: =IF(A37<>"",DATA_RELATIONSHIPS!G34,"") | I37: =IF(A37<>"",""&DATA_RELATIONSHIPS!H34,"") | J37: =IF(A37<>"",""&DATA_RELATIONSHIPS!I34,"")
A38: =IF(DATA_RELATIONSHIPS!B35<>"",""&DATA_RELATIONSHIPS!B35,"") | B38: =IF(A38<>"",""&DATA_RELATIONSHIPS!C35,"") | C38: =IF(A38<>"","KO","") | D38: =IF(A38<>"",""&DATA_RELATIONSHIPS!D35,"") | E38: =IF(A38<>"","KO","") | F38: =IF(A38<>"",""&DATA_RELATIONSHIPS!F35,"") | G38: =IF(A38<>"",DATA_RELATIONSHIPS!G35,"") | H38: =IF(A38<>"",DATA_RELATIONSHIPS!G35,"") | I38: =IF(A38<>"",""&DATA_RELATIONSHIPS!H35,"") | J38: =IF(A38<>"",""&DATA_RELATIONSHIPS!I35,"")
A39: =IF(DATA_RELATIONSHIPS!B36<>"",""&DATA_RELATIONSHIPS!B36,"") | B39: =IF(A39<>"",""&DATA_RELATIONSHIPS!C36,"") | C39: =IF(A39<>"","KO","") | D39: =IF(A39<>"",""&DATA_RELATIONSHIPS!D36,"") | E39: =IF(A39<>"","KO","") | F39: =IF(A39<>"",""&DATA_RELATIONSHIPS!F36,"") | G39: =IF(A39<>"",DATA_RELATIONSHIPS!G36,"") | H39: =IF(A39<>"",DATA_RELATIONSHIPS!G36,"") | I39: =IF(A39<>"",""&DATA_RELATIONSHIPS!H36,"") | J39: =IF(A39<>"",""&DATA_RELATIONSHIPS!I36,"")
... A154: =IF(DATA_RELATIONSHIPS!B151<>"",""&DATA_RELATIONSHIPS!B151,"") | B154: =IF(A154<>"",""&DATA_RELATIONSHIPS!C151,"") | C154: =IF(A154<>"","KO","") | D154: =IF(A154<>"",""&DATA_RELATIONSHIPS!D151,"") | E154: =IF(A154<>"","KO","") | F154: =IF(A154<>"",""&DATA_RELATIONSHIPS!F151,"") | G154: =IF(A154<>"",DATA_RELATIONSHIPS!G151,"") | H154: =IF(A154<>"",DATA_RELATIONSHIPS!G151,"") | I154: =IF(A154<>"",""&DATA_RELATIONSHIPS!H151,"") | J154: =IF(A154<>"",""&DATA_RELATIONSHIPS!I151,"")

Sheet 04_Lineage_Explorer
A1: RESEARCH INTELLIGENCE ENGINE (RIE) — EPISTEMIC LINEAGE EXPLORER
A2: 4-Tier Vertical Evidence Tracing (KO ➔ IO ➔ EO ➔ Source) | Automated Lineage Health & Provenance Grounding
A4: NAVIGATION: | B4: =HYPERLINK("#'01_Executive_Dashboard'!A1", "⮌ BACK TO DASHBOARD") | C4: =HYPERLINK("#'02_Object_Registry'!A1", "➔ OBJECT REGISTRY") | D4: =HYPERLINK("#'03_Relationship_Registry'!A1", "➔ RELATIONSHIP REGISTRY") | E4: =HYPERLINK("#'05_Knowledge_Frontier'!A1", "➔ KNOWLEDGE FRONTIER") | F4: =HYPERLINK("#'06_Provenance_Register'!A1", "➔ PROVENANCE REGISTER") | G4: =HYPERLINK("#'07_Human_Decision_Log'!A1", "➔ DECISION LOG") | H4: =HYPERLINK("#'DATA_KO'!A1", "➔ REPOSITORY DATA")
A6: Target Knowledge Object (KO): | B6: =IF(D6<>"", D6, IF('01_Executive_Dashboard'!$C$21<>"", '01_Executive_Dashboard'!$C$21, '01_Executive_Dashboard'!$A$26)) | C6: Direct Override Selector: | E6: =HYPERLINK("#'01_Executive_Dashboard'!C21", "➔ [Select on Dashboard]") | F6: {=IFERROR(INDEX('05_Knowledge_Frontier'!H:H, MATCH($B$6, '05_Knowledge_Frontier'!B:B, 0)), "PENDING_ARCHITECT")} | G6: Review Action Link: | H6: =HYPERLINK("#'05_Knowledge_Frontier'!A" & IFERROR(MATCH($B$6, '05_Knowledge_Frontier'!B:B, 0), 1), "➔ Evaluate in Review Queue")
A7: Calculated Lineage Chain: | B7: {="Origin: " & INDEX(DATA_KO!D:D, MATCH(B6, DATA_KO!A:A, 0)) & " | Confidence: " & TEXT(INDEX(DATA_KO!G:G, MATCH(B6, DATA_KO!A:A, 0)), "0.00") & " | EO Count: " & (LEN(INDEX(DATA_KO!E:E, MATCH(B6, DATA_KO!A:A, 0)))-LEN(SUBSTITUTE(INDEX(DATA_KO!E:E, MATCH(B6, DATA_KO!A:A, 0)), ",", ""))+1) & " | Supporting IOs: " & INDEX(DATA_KO!F:F, MATCH(B6, DATA_KO!A:A, 0))}
A9: 1. KNOWLEDGE CLAIM (SYNTHESIZED THESIS & DOMAIN)
A10: Concept Title: | B10: {=INDEX(DATA_KO!B:B, MATCH($B$6, DATA_KO!A:A, 0))} | F10: Ratification State: | G10: {=INDEX(DATA_KO!I:I, MATCH($B$6, DATA_KO!A:A, 0))}
A11: Domain / Field: | B11: {=INDEX(DATA_KO!C:C, MATCH($B$6, DATA_KO!A:A, 0))} | F11: Epistemic Confidence: | G11: {=TEXT(INDEX(DATA_KO!G:G, MATCH($B$6, DATA_KO!A:A, 0)), "0.00")}
A13: 2. SUPPORTING INTERPRETATIONS (PRIMARY HYPOTHESES & MODELS)
A14: Core Research Inquiry (?): | B14: {=INDEX(DATA_IO!B:B, MATCH(TRIM(MID(SUBSTITUTE(INDEX(DATA_KO!F:F, MATCH($B$6, DATA_KO!A:A, 0)), ",", REPT(" ", 500)), 1, 500)), DATA_IO!A:A, 0))} | F14: Model IO ID: | G14: {=TRIM(MID(SUBSTITUTE(INDEX(DATA_KO!F:F, MATCH($B$6, DATA_KO!A:A, 0)), ",", REPT(" ", 500)), 1, 500))}
A15: Primary Model (Hypothesis A): | B15: {=INDEX(DATA_IO!C:C, MATCH(TRIM(MID(SUBSTITUTE(INDEX(DATA_KO!F:F, MATCH($B$6, DATA_KO!A:A, 0)), ",", REPT(" ", 500)), 1, 500)), DATA_IO!A:A, 0))} | F15: Model Confidence: | G15: {=TEXT(INDEX(DATA_IO!G:G, MATCH(TRIM(MID(SUBSTITUTE(INDEX(DATA_KO!F:F, MATCH($B$6, DATA_KO!A:A, 0)), ",", REPT(" ", 500)), 1, 500)), DATA_IO!A:A, 0)), "0.00")}
A17: 3. COMPETING INTERPRETATIONS (FALSIFICATION & COUNTER-HYPOTHESES)
A18: Competing Counter-Hypothesis B: | B18: {=INDEX(DATA_IO!D:D, MATCH(TRIM(MID(SUBSTITUTE(INDEX(DATA_KO!F:F, MATCH($B$6, DATA_KO!A:A, 0)), ",", REPT(" ", 500)), 1, 500)), DATA_IO!A:A, 0))} | F18: Future Research Trigger: | G18: {=INDEX(DATA_IO!I:I, MATCH(TRIM(MID(SUBSTITUTE(INDEX(DATA_KO!F:F, MATCH($B$6, DATA_KO!A:A, 0)), ",", REPT(" ", 500)), 1, 500)), DATA_IO!A:A, 0))}
A20: 4. EVIDENCE PROFILE (GROUND TRUTH EMPIRICAL OBSERVATIONS)
A21: Evidence_Object_ID | B21: Source_ID | C21: Timestamp / Page | D21: Presenter / Analyst | E21: Evidence Type | F21: Direct Empirical Observation
A22: {=IFERROR(TRIM(MID(SUBSTITUTE(INDEX(DATA_KO!E:E, MATCH($B$6, DATA_KO!A:A, 0)), ",", REPT(" ", 500)), (1-1)*500+1, 500)), "")} | B22: {=IF(A22="","", IFERROR(INDEX(DATA_EO!B:B, MATCH(A22, DATA_EO!A:A, 0)), "SOURCE_GAP"))} | C22: {=IF(A22="","", IFERROR(INDEX(DATA_EO!J:J, MATCH(A22, DATA_EO!A:A, 0)), "N/A"))} | D22: {=IF(A22="","", IFERROR(INDEX(DATA_EO!D:D, MATCH(A22, DATA_EO!A:A, 0)), "N/A"))} | E22: {=IF(A22="","", IFERROR(INDEX(DATA_EO!K:K, MATCH(A22, DATA_EO!A:A, 0)), "N/A"))} | F22: {=IF(A22="","", IFERROR(INDEX(DATA_EO!L:L, MATCH(A22, DATA_EO!A:A, 0)), "N/A"))}
A23: {=IFERROR(TRIM(MID(SUBSTITUTE(INDEX(DATA_KO!E:E, MATCH($B$6, DATA_KO!A:A, 0)), ",", REPT(" ", 500)), (2-1)*500+1, 500)), "")} | B23: {=IF(A23="","", IFERROR(INDEX(DATA_EO!B:B, MATCH(A23, DATA_EO!A:A, 0)), "SOURCE_GAP"))} | C23: {=IF(A23="","", IFERROR(INDEX(DATA_EO!J:J, MATCH(A23, DATA_EO!A:A, 0)), "N/A"))} | D23: {=IF(A23="","", IFERROR(INDEX(DATA_EO!D:D, MATCH(A23, DATA_EO!A:A, 0)), "N/A"))} | E23: {=IF(A23="","", IFERROR(INDEX(DATA_EO!K:K, MATCH(A23, DATA_EO!A:A, 0)), "N/A"))} | F23: {=IF(A23="","", IFERROR(INDEX(DATA_EO!L:L, MATCH(A23, DATA_EO!A:A, 0)), "N/A"))}
A24: {=IFERROR(TRIM(MID(SUBSTITUTE(INDEX(DATA_KO!E:E, MATCH($B$6, DATA_KO!A:A, 0)), ",", REPT(" ", 500)), (3-1)*500+1, 500)), "")} | B24: {=IF(A24="","", IFERROR(INDEX(DATA_EO!B:B, MATCH(A24, DATA_EO!A:A, 0)), "SOURCE_GAP"))} | C24: {=IF(A24="","", IFERROR(INDEX(DATA_EO!J:J, MATCH(A24, DATA_EO!A:A, 0)), "N/A"))} | D24: {=IF(A24="","", IFERROR(INDEX(DATA_EO!D:D, MATCH(A24, DATA_EO!A:A, 0)), "N/A"))} | E24: {=IF(A24="","", IFERROR(INDEX(DATA_EO!K:K, MATCH(A24, DATA_EO!A:A, 0)), "N/A"))} | F24: {=IF(A24="","", IFERROR(INDEX(DATA_EO!L:L, MATCH(A24, DATA_EO!A:A, 0)), "N/A"))}
A26: 5. SOURCE RECORDS & CRYPTOGRAPHIC PROVENANCE
A27: Origin Media Source Anchor: | B27: {=INDEX(DATA_KO!D:D, MATCH($B$6, DATA_KO!A:A, 0))} | D27: Speaker / Channel: | E27: {=INDEX(DATA_EO!D:D, MATCH(A22, DATA_EO!A:A, 0)) & " (" & INDEX(DATA_EO!E:E, MATCH(A22, DATA_EO!A:A, 0)) & ")"} | G27: Obsidian Second-Brain Link: | H27: ="[[" & $B$6 & "]]"
A29: HUMAN GOVERNANCE DECISION: | B29: =HYPERLINK("#'07_Human_Decision_Log'!A1", "➔ [ RECORD FORMAL HUMAN DECISION IN DECISION LOG (ACCEPT / HOLD / REJECT / FURTHER RESEARCH) ]")
A45: =DATA_KO!A18 | B45: =DATA_KO!B18 | C45: =DATA_KO!C18 | D45: =DATA_KO!D18 | E45: =IF(DATA_KO!F18="","", LEN(DATA_KO!F18)-LEN(SUBSTITUTE(DATA_KO!F18, ",", ""))+1) | F45: =IF(DATA_KO!E18="","", LEN(DATA_KO!E18)-LEN(SUBSTITUTE(DATA_KO!E18, ",", ""))+1) | G45: =IF(OR(DATA_KO!E18="", DATA_KO!F18=""), "BROKEN_LINEAGE", IF(DATA_KO!H18="QUARANTINED_SYNTHETIC_FIXTURE", "QUARANTINED_FIXTURE", IF(OR(DATA_KO!H18="CANDIDATE", DATA_KO!G18<0.8), "WARNING_REVIEW_REQUIRED", "VERIFIED_COMPLETE"))) | H45: =IF(G45="BROKEN_LINEAGE", "HALT: RESOLVE DANGLING OBJECT", IF(G45="QUARANTINED_FIXTURE", "EXCLUDED: QUARANTINED SYNTHETIC FIXTURE", IF(G45="WARNING_REVIEW_REQUIRED", "QUEUE FOR LEVEL 5 RATIFICATION", "RATIFIED CANONICAL")))
A46: =DATA_KO!A19 | B46: =DATA_KO!B19 | C46: =DATA_KO!C19 | D46: =DATA_KO!D19 | E46: =IF(DATA_KO!F19="","", LEN(DATA_KO!F19)-LEN(SUBSTITUTE(DATA_KO!F19, ",", ""))+1) | F46: =IF(DATA_KO!E19="","", LEN(DATA_KO!E19)-LEN(SUBSTITUTE(DATA_KO!E19, ",", ""))+1) | G46: =IF(OR(DATA_KO!E19="", DATA_KO!F19=""), "BROKEN_LINEAGE", IF(DATA_KO!H19="QUARANTINED_SYNTHETIC_FIXTURE", "QUARANTINED_FIXTURE", IF(OR(DATA_KO!H19="CANDIDATE", DATA_KO!G19<0.8), "WARNING_REVIEW_REQUIRED", "VERIFIED_COMPLETE"))) | H46: =IF(G46="BROKEN_LINEAGE", "HALT: RESOLVE DANGLING OBJECT", IF(G46="QUARANTINED_FIXTURE", "EXCLUDED: QUARANTINED SYNTHETIC FIXTURE", IF(G46="WARNING_REVIEW_REQUIRED", "QUEUE FOR LEVEL 5 RATIFICATION", "RATIFIED CANONICAL")))

Sheet 05_Knowledge_Frontier
A1: RESEARCH INTELLIGENCE ENGINE (RIE) — HUMAN KNOWLEDGE REVIEW WORKFLOW | J1: =HYPERLINK("#'01_Executive_Dashboard'!A1", "⮌ BACK TO DASHBOARD")
